
[I 120806 15:19:02 autoreload:175] /root/bipapa/app.py modified; restarting server
[I 120806 15:19:07 web:1447] 200 GET / (192.168.32.17) 376.87ms
[W 120806 15:19:09 web:1447] 404 GET /favicon.ico (192.168.32.17) 0.90ms
[I 120806 15:19:09 web:1447] 304 GET / (192.168.32.17) 361.82ms
[W 120806 15:19:09 web:1447] 404 GET /favicon.ico (192.168.32.17) 0.87ms
[I 120806 15:19:34 web:1447] 200 GET / (192.168.32.17) 371.68ms
[W 120806 15:19:36 web:1447] 404 GET /favicon.ico (192.168.32.17) 0.87ms
[I 120806 15:19:58 web:1447] 304 GET / (192.168.32.17) 366.66ms
[W 120806 15:19:59 web:1447] 404 GET /favicon.ico (192.168.32.17) 0.87ms
[I 120806 15:20:29 web:1447] 304 GET / (192.168.32.17) 373.90ms
[W 120806 15:20:30 web:1447] 404 GET /favicon.ico (192.168.32.17) 0.87ms
[I 120806 15:23:07 web:1447] 304 GET / (192.168.32.17) 370.87ms
[I 120806 15:24:13 web:1447] 304 GET / (192.168.32.17) 371.20ms
[I 120806 15:28:20 autoreload:175] /root/bipapa/app.py modified; restarting server
[E 120806 15:28:24 web:1064] Uncaught exception GET / (192.168.32.17)
    HTTPRequest(protocol='http', host='10.24.94.36:8888', method='GET', uri='/', version='HTTP/1.1', remote_ip='192.168.32.17', body='', headers={'Accept-Language': 'ja,en-US;q=0.8,en;q=0.6,zh-CN;q=0.4,zh;q=0.2,zh-TW;q=0.2', 'Accept-Encoding': 'gzip,deflate,sdch', 'Host': '10.24.94.36:8888', 'Accept': 'text/html,application/xhtml+xml,application/xml;q=0.9,*/*;q=0.8', 'User-Agent': 'Mozilla/5.0 (Windows NT 6.1) AppleWebKit/537.1 (KHTML, like Gecko) Chrome/21.0.1180.60 Safari/537.1', 'Accept-Charset': 'UTF-8,*;q=0.5', 'Connection': 'keep-alive', 'If-None-Match': '"140cfdb7c9d35b5761d215f1c184d429ee82f603"'})
    Traceback (most recent call last):
      File "/usr/lib/python2.6/site-packages/tornado/web.py", line 1021, in _execute
        getattr(self, self.request.method.lower())(*args, **kwargs)
      File "/root/bipapa/app.py", line 151, in get
        img_list = getimg4db()
      File "/root/bipapa/app.py", line 146, in getimg4db
        db.close()
      File "/usr/lib64/python2.6/site-packages/pymongo/collection.py", line 1193, in __call__
        self.__name)
    TypeError: 'Collection' object is not callable. If you meant to call the 'close' method on a 'Database' object it is failing because no such method exists.
[E 120806 15:28:24 web:1447] 500 GET / (192.168.32.17) 90.44ms
[W 120806 15:28:25 web:1447] 404 GET /favicon.ico (192.168.32.17) 0.39ms
[I 120806 15:28:44 autoreload:175] /root/bipapa/app.py modified; restarting server
[I 120806 15:28:44 web:1447] 200 GET / (192.168.32.17) 384.21ms
[W 120806 15:28:46 web:1447] 404 GET /favicon.ico (192.168.32.17) 0.91ms
[I 120806 16:02:43 web:1447] 304 GET / (192.168.32.17) 371.14ms
[I 120806 17:30:07 autoreload:175] /root/bipapa/app.py modified; restarting server
[I 120806 17:33:56 autoreload:175] /root/bipapa/app.py modified; restarting server
[E 120806 17:33:59 web:1064] Uncaught exception GET / (192.168.32.17)
    HTTPRequest(protocol='http', host='10.24.94.36:8888', method='GET', uri='/', version='HTTP/1.1', remote_ip='192.168.32.17', body='', headers={'Accept-Language': 'ja,en-US;q=0.8,en;q=0.6,zh-CN;q=0.4,zh;q=0.2,zh-TW;q=0.2', 'Accept-Encoding': 'gzip,deflate,sdch', 'Host': '10.24.94.36:8888', 'Accept': 'text/html,application/xhtml+xml,application/xml;q=0.9,*/*;q=0.8', 'User-Agent': 'Mozilla/5.0 (Windows NT 6.1) AppleWebKit/537.1 (KHTML, like Gecko) Chrome/21.0.1180.60 Safari/537.1', 'Accept-Charset': 'UTF-8,*;q=0.5', 'Connection': 'keep-alive', 'If-None-Match': '"140cfdb7c9d35b5761d215f1c184d429ee82f603"'})
    Traceback (most recent call last):
      File "/usr/lib/python2.6/site-packages/tornado/web.py", line 1021, in _execute
        getattr(self, self.request.method.lower())(*args, **kwargs)
      File "/root/bipapa/app.py", line 154, in get
        img,content_type = getimg4db()
    TypeError: getimg4db() takes exactly 1 argument (0 given)
[E 120806 17:33:59 web:1447] 500 GET / (192.168.32.17) 1.47ms
[W 120806 17:34:00 web:1447] 404 GET /favicon.ico (192.168.32.17) 0.38ms
[I 120806 17:34:24 autoreload:175] /root/bipapa/app.py modified; restarting server
[E 120806 17:34:26 web:1064] Uncaught exception GET / (192.168.32.17)
    HTTPRequest(protocol='http', host='10.24.94.36:8888', method='GET', uri='/', version='HTTP/1.1', remote_ip='192.168.32.17', body='', headers={'Accept-Language': 'ja,en-US;q=0.8,en;q=0.6,zh-CN;q=0.4,zh;q=0.2,zh-TW;q=0.2', 'Accept-Encoding': 'gzip,deflate,sdch', 'Host': '10.24.94.36:8888', 'Accept': 'text/html,application/xhtml+xml,application/xml;q=0.9,*/*;q=0.8', 'User-Agent': 'Mozilla/5.0 (Windows NT 6.1) AppleWebKit/537.1 (KHTML, like Gecko) Chrome/21.0.1180.60 Safari/537.1', 'Accept-Charset': 'UTF-8,*;q=0.5', 'Connection': 'keep-alive', 'Cache-Control': 'max-age=0'})
    Traceback (most recent call last):
      File "/usr/lib/python2.6/site-packages/tornado/web.py", line 1021, in _execute
        getattr(self, self.request.method.lower())(*args, **kwargs)
      File "/root/bipapa/app.py", line 154, in get
        img,content_type = getimg4db("501b745a41ab10241f6d0393")
      File "/root/bipapa/app.py", line 139, in getimg4db
        f = fs.get_version(filename="%s" %finemae)
    NameError: global name 'finemae' is not defined
[E 120806 17:34:26 web:1447] 500 GET / (192.168.32.17) 4.07ms
[W 120806 17:34:26 web:1447] 404 GET /favicon.ico (192.168.32.17) 0.37ms
[I 120806 17:34:36 autoreload:175] /root/bipapa/app.py modified; restarting server
[I 120806 17:34:38 web:1447] 200 GET / (192.168.32.17) 6.34ms
[W 120806 17:34:39 web:1447] 404 GET /favicon.ico (192.168.32.17) 0.90ms
[I 120806 17:39:24 autoreload:175] /root/bipapa/app.py modified; restarting server
[I 120806 17:52:03 autoreload:175] /root/bipapa/app.py modified; restarting server
[I 120806 17:52:07 web:1447] 304 GET / (192.168.32.17) 6.27ms
[W 120806 17:52:08 web:1447] 404 GET /favicon.ico (192.168.32.17) 0.99ms
[I 120806 17:53:28 autoreload:175] /root/bipapa/app.py modified; restarting server
[I 120806 17:53:45 autoreload:175] /root/bipapa/app.py modified; restarting server
[I 120806 17:59:13 autoreload:175] /root/bipapa/app.py modified; restarting server
[I 120806 17:59:15 web:1447] 304 GET / (192.168.32.17) 6.87ms
[W 120806 17:59:16 web:1447] 404 GET /favicon.ico (192.168.32.17) 0.95ms
[I 120806 18:08:27 autoreload:175] /root/bipapa/app.py modified; restarting server
[I 120806 18:09:37 web:1447] 200 GET / (192.168.32.17) 9.38ms
[E 120806 18:09:37 web:1064] Uncaught exception GET / (192.168.32.17)
    HTTPRequest(protocol='http', host='10.24.94.36:8888', method='GET', uri='/', version='HTTP/1.1', remote_ip='192.168.32.17', body='', headers={'Accept-Language': 'ja,en-US;q=0.8,en;q=0.6,zh-CN;q=0.4,zh;q=0.2,zh-TW;q=0.2', 'Accept-Encoding': 'gzip,deflate,sdch', 'Host': '10.24.94.36:8888', 'Accept': 'text/html,application/xhtml+xml,application/xml;q=0.9,*/*;q=0.8', 'User-Agent': 'Mozilla/5.0 (Windows NT 6.1) AppleWebKit/537.1 (KHTML, like Gecko) Chrome/21.0.1180.60 Safari/537.1', 'Accept-Charset': 'UTF-8,*;q=0.5', 'Connection': 'keep-alive', 'Cache-Control': 'max-age=0'})
    Traceback (most recent call last):
      File "/usr/lib/python2.6/site-packages/tornado/web.py", line 1000, in _stack_context_handle_exception
        raise_exc_info((type, value, traceback))
      File "/usr/lib/python2.6/site-packages/tornado/web.py", line 1118, in wrapper
        return method(self, *args, **kwargs)
      File "/root/bipapa/app.py", line 165, in get
        self.write(img)
      File "/usr/lib/python2.6/site-packages/tornado/web.py", line 487, in write
        raise RuntimeError("Cannot write() after finish().  May be caused "
    RuntimeError: Cannot write() after finish().  May be caused by using async operations without the @asynchronous decorator.
[E 120806 18:09:37 web:718] Cannot send error response after headers written
[W 120806 18:09:38 web:1447] 404 GET /favicon.ico (192.168.32.17) 0.42ms
[I 120806 18:09:38 web:1447] 304 GET / (192.168.32.17) 7.02ms
[E 120806 18:09:38 web:1064] Uncaught exception GET / (192.168.32.17)
    HTTPRequest(protocol='http', host='10.24.94.36:8888', method='GET', uri='/', version='HTTP/1.1', remote_ip='192.168.32.17', body='', headers={'Accept-Language': 'ja,en-US;q=0.8,en;q=0.6,zh-CN;q=0.4,zh;q=0.2,zh-TW;q=0.2', 'Accept-Encoding': 'gzip,deflate,sdch', 'Host': '10.24.94.36:8888', 'Accept': '*/*', 'User-Agent': 'Mozilla/5.0 (Windows NT 6.1) AppleWebKit/537.1 (KHTML, like Gecko) Chrome/21.0.1180.60 Safari/537.1', 'Accept-Charset': 'UTF-8,*;q=0.5', 'Connection': 'keep-alive', 'Referer': 'http://10.24.94.36:8888/', 'If-None-Match': '"857198b8da3e515e9a3b16a0981530ca83323c8e"'})
    Traceback (most recent call last):
      File "/usr/lib/python2.6/site-packages/tornado/web.py", line 1000, in _stack_context_handle_exception
        raise_exc_info((type, value, traceback))
      File "/usr/lib/python2.6/site-packages/tornado/web.py", line 1118, in wrapper
        return method(self, *args, **kwargs)
      File "/root/bipapa/app.py", line 165, in get
        self.write(img)
      File "/usr/lib/python2.6/site-packages/tornado/web.py", line 487, in write
        raise RuntimeError("Cannot write() after finish().  May be caused "
    RuntimeError: Cannot write() after finish().  May be caused by using async operations without the @asynchronous decorator.
[E 120806 18:09:38 web:718] Cannot send error response after headers written
[I 120806 18:09:40 web:1447] 304 GET / (192.168.32.17) 6.89ms
[E 120806 18:09:40 web:1064] Uncaught exception GET / (192.168.32.17)
    HTTPRequest(protocol='http', host='10.24.94.36:8888', method='GET', uri='/', version='HTTP/1.1', remote_ip='192.168.32.17', body='', headers={'Accept-Language': 'ja,en-US;q=0.8,en;q=0.6,zh-CN;q=0.4,zh;q=0.2,zh-TW;q=0.2', 'Accept-Encoding': 'gzip,deflate,sdch', 'Host': '10.24.94.36:8888', 'Accept': 'text/html,application/xhtml+xml,application/xml;q=0.9,*/*;q=0.8', 'User-Agent': 'Mozilla/5.0 (Windows NT 6.1) AppleWebKit/537.1 (KHTML, like Gecko) Chrome/21.0.1180.60 Safari/537.1', 'Accept-Charset': 'UTF-8,*;q=0.5', 'Connection': 'keep-alive', 'Cache-Control': 'max-age=0', 'If-None-Match': '"857198b8da3e515e9a3b16a0981530ca83323c8e"'})
    Traceback (most recent call last):
      File "/usr/lib/python2.6/site-packages/tornado/web.py", line 1000, in _stack_context_handle_exception
        raise_exc_info((type, value, traceback))
      File "/usr/lib/python2.6/site-packages/tornado/web.py", line 1118, in wrapper
        return method(self, *args, **kwargs)
      File "/root/bipapa/app.py", line 165, in get
        self.write(img)
      File "/usr/lib/python2.6/site-packages/tornado/web.py", line 487, in write
        raise RuntimeError("Cannot write() after finish().  May be caused "
    RuntimeError: Cannot write() after finish().  May be caused by using async operations without the @asynchronous decorator.
[E 120806 18:09:40 web:718] Cannot send error response after headers written
[W 120806 18:09:40 web:1447] 404 GET /favicon.ico (192.168.32.17) 0.35ms
[I 120806 18:13:04 autoreload:175] /root/bipapa/app.py modified; restarting server
[I 120806 18:13:06 web:1447] 200 GET / (192.168.32.17) 9.48ms
[E 120806 18:13:06 web:1064] Uncaught exception GET / (192.168.32.17)
    HTTPRequest(protocol='http', host='10.24.94.36:8888', method='GET', uri='/', version='HTTP/1.1', remote_ip='192.168.32.17', body='', headers={'Accept-Language': 'ja,en-US;q=0.8,en;q=0.6,zh-CN;q=0.4,zh;q=0.2,zh-TW;q=0.2', 'Accept-Encoding': 'gzip,deflate,sdch', 'Host': '10.24.94.36:8888', 'Accept': 'text/html,application/xhtml+xml,application/xml;q=0.9,*/*;q=0.8', 'User-Agent': 'Mozilla/5.0 (Windows NT 6.1) AppleWebKit/537.1 (KHTML, like Gecko) Chrome/21.0.1180.60 Safari/537.1', 'Accept-Charset': 'UTF-8,*;q=0.5', 'Connection': 'keep-alive', 'Cache-Control': 'max-age=0', 'If-None-Match': '"857198b8da3e515e9a3b16a0981530ca83323c8e"'})
    Traceback (most recent call last):
      File "/usr/lib/python2.6/site-packages/tornado/web.py", line 1000, in _stack_context_handle_exception
        raise_exc_info((type, value, traceback))
      File "/usr/lib/python2.6/site-packages/tornado/web.py", line 1118, in wrapper
        return method(self, *args, **kwargs)
      File "/root/bipapa/app.py", line 165, in get
        self.write(img)
      File "/usr/lib/python2.6/site-packages/tornado/web.py", line 487, in write
        raise RuntimeError("Cannot write() after finish().  May be caused "
    RuntimeError: Cannot write() after finish().  May be caused by using async operations without the @asynchronous decorator.
[E 120806 18:13:06 web:718] Cannot send error response after headers written
[I 120806 18:13:06 web:1447] 200 GET / (192.168.32.17) 7.25ms
[E 120806 18:13:06 web:1064] Uncaught exception GET / (192.168.32.17)
    HTTPRequest(protocol='http', host='10.24.94.36:8888', method='GET', uri='/', version='HTTP/1.1', remote_ip='192.168.32.17', body='', headers={'Accept-Language': 'ja,en-US;q=0.8,en;q=0.6,zh-CN;q=0.4,zh;q=0.2,zh-TW;q=0.2', 'Accept-Encoding': 'gzip,deflate,sdch', 'Host': '10.24.94.36:8888', 'Accept': '*/*', 'User-Agent': 'Mozilla/5.0 (Windows NT 6.1) AppleWebKit/537.1 (KHTML, like Gecko) Chrome/21.0.1180.60 Safari/537.1', 'Accept-Charset': 'UTF-8,*;q=0.5', 'Connection': 'keep-alive', 'Referer': 'http://10.24.94.36:8888/', 'Cache-Control': 'max-age=0', 'If-None-Match': '"857198b8da3e515e9a3b16a0981530ca83323c8e"'})
    Traceback (most recent call last):
      File "/usr/lib/python2.6/site-packages/tornado/web.py", line 1000, in _stack_context_handle_exception
        raise_exc_info((type, value, traceback))
      File "/usr/lib/python2.6/site-packages/tornado/web.py", line 1118, in wrapper
        return method(self, *args, **kwargs)
      File "/root/bipapa/app.py", line 165, in get
        self.write(img)
      File "/usr/lib/python2.6/site-packages/tornado/web.py", line 487, in write
        raise RuntimeError("Cannot write() after finish().  May be caused "
    RuntimeError: Cannot write() after finish().  May be caused by using async operations without the @asynchronous decorator.
[E 120806 18:13:06 web:718] Cannot send error response after headers written
[W 120806 18:13:06 web:1447] 404 GET /favicon.ico (192.168.32.17) 0.44ms
[I 120806 18:13:07 web:1447] 304 GET / (192.168.32.17) 7.03ms
[E 120806 18:13:07 web:1064] Uncaught exception GET / (192.168.32.17)
    HTTPRequest(protocol='http', host='10.24.94.36:8888', method='GET', uri='/', version='HTTP/1.1', remote_ip='192.168.32.17', body='', headers={'Accept-Language': 'ja,en-US;q=0.8,en;q=0.6,zh-CN;q=0.4,zh;q=0.2,zh-TW;q=0.2', 'Accept-Encoding': 'gzip,deflate,sdch', 'Host': '10.24.94.36:8888', 'Accept': 'text/html,application/xhtml+xml,application/xml;q=0.9,*/*;q=0.8', 'User-Agent': 'Mozilla/5.0 (Windows NT 6.1) AppleWebKit/537.1 (KHTML, like Gecko) Chrome/21.0.1180.60 Safari/537.1', 'Accept-Charset': 'UTF-8,*;q=0.5', 'Connection': 'keep-alive', 'Cache-Control': 'max-age=0', 'If-None-Match': '"066fe9dcdcfe491731c759c07fceb62b561bf663"'})
    Traceback (most recent call last):
      File "/usr/lib/python2.6/site-packages/tornado/web.py", line 1000, in _stack_context_handle_exception
        raise_exc_info((type, value, traceback))
      File "/usr/lib/python2.6/site-packages/tornado/web.py", line 1118, in wrapper
        return method(self, *args, **kwargs)
      File "/root/bipapa/app.py", line 165, in get
        self.write(img)
      File "/usr/lib/python2.6/site-packages/tornado/web.py", line 487, in write
        raise RuntimeError("Cannot write() after finish().  May be caused "
    RuntimeError: Cannot write() after finish().  May be caused by using async operations without the @asynchronous decorator.
[E 120806 18:13:07 web:718] Cannot send error response after headers written
[W 120806 18:13:07 web:1447] 404 GET /favicon.ico (192.168.32.17) 0.35ms
[I 120806 18:13:08 web:1447] 304 GET / (192.168.32.17) 6.80ms
[E 120806 18:13:08 web:1064] Uncaught exception GET / (192.168.32.17)
    HTTPRequest(protocol='http', host='10.24.94.36:8888', method='GET', uri='/', version='HTTP/1.1', remote_ip='192.168.32.17', body='', headers={'Accept-Language': 'ja,en-US;q=0.8,en;q=0.6,zh-CN;q=0.4,zh;q=0.2,zh-TW;q=0.2', 'Accept-Encoding': 'gzip,deflate,sdch', 'Host': '10.24.94.36:8888', 'Accept': 'text/html,application/xhtml+xml,application/xml;q=0.9,*/*;q=0.8', 'User-Agent': 'Mozilla/5.0 (Windows NT 6.1) AppleWebKit/537.1 (KHTML, like Gecko) Chrome/21.0.1180.60 Safari/537.1', 'Accept-Charset': 'UTF-8,*;q=0.5', 'Connection': 'keep-alive', 'Cache-Control': 'max-age=0', 'If-None-Match': '"066fe9dcdcfe491731c759c07fceb62b561bf663"'})
    Traceback (most recent call last):
      File "/usr/lib/python2.6/site-packages/tornado/web.py", line 1000, in _stack_context_handle_exception
        raise_exc_info((type, value, traceback))
      File "/usr/lib/python2.6/site-packages/tornado/web.py", line 1118, in wrapper
        return method(self, *args, **kwargs)
      File "/root/bipapa/app.py", line 165, in get
        self.write(img)
      File "/usr/lib/python2.6/site-packages/tornado/web.py", line 487, in write
        raise RuntimeError("Cannot write() after finish().  May be caused "
    RuntimeError: Cannot write() after finish().  May be caused by using async operations without the @asynchronous decorator.
[E 120806 18:13:08 web:718] Cannot send error response after headers written
[W 120806 18:13:08 web:1447] 404 GET /favicon.ico (192.168.32.17) 0.36ms
[I 120806 18:13:08 web:1447] 304 GET / (192.168.32.17) 6.96ms
[E 120806 18:13:08 web:1064] Uncaught exception GET / (192.168.32.17)
    HTTPRequest(protocol='http', host='10.24.94.36:8888', method='GET', uri='/', version='HTTP/1.1', remote_ip='192.168.32.17', body='', headers={'Accept-Language': 'ja,en-US;q=0.8,en;q=0.6,zh-CN;q=0.4,zh;q=0.2,zh-TW;q=0.2', 'Accept-Encoding': 'gzip,deflate,sdch', 'Host': '10.24.94.36:8888', 'Accept': 'text/html,application/xhtml+xml,application/xml;q=0.9,*/*;q=0.8', 'User-Agent': 'Mozilla/5.0 (Windows NT 6.1) AppleWebKit/537.1 (KHTML, like Gecko) Chrome/21.0.1180.60 Safari/537.1', 'Accept-Charset': 'UTF-8,*;q=0.5', 'Connection': 'keep-alive', 'Cache-Control': 'max-age=0', 'If-None-Match': '"066fe9dcdcfe491731c759c07fceb62b561bf663"'})
    Traceback (most recent call last):
      File "/usr/lib/python2.6/site-packages/tornado/web.py", line 1000, in _stack_context_handle_exception
        raise_exc_info((type, value, traceback))
      File "/usr/lib/python2.6/site-packages/tornado/web.py", line 1118, in wrapper
        return method(self, *args, **kwargs)
      File "/root/bipapa/app.py", line 165, in get
        self.write(img)
      File "/usr/lib/python2.6/site-packages/tornado/web.py", line 487, in write
        raise RuntimeError("Cannot write() after finish().  May be caused "
    RuntimeError: Cannot write() after finish().  May be caused by using async operations without the @asynchronous decorator.
[E 120806 18:13:08 web:718] Cannot send error response after headers written
[W 120806 18:13:09 web:1447] 404 GET /favicon.ico (192.168.32.17) 0.36ms
[I 120806 18:13:09 web:1447] 304 GET / (192.168.32.17) 7.06ms
[E 120806 18:13:09 web:1064] Uncaught exception GET / (192.168.32.17)
    HTTPRequest(protocol='http', host='10.24.94.36:8888', method='GET', uri='/', version='HTTP/1.1', remote_ip='192.168.32.17', body='', headers={'Accept-Language': 'ja,en-US;q=0.8,en;q=0.6,zh-CN;q=0.4,zh;q=0.2,zh-TW;q=0.2', 'Accept-Encoding': 'gzip,deflate,sdch', 'Host': '10.24.94.36:8888', 'Accept': 'text/html,application/xhtml+xml,application/xml;q=0.9,*/*;q=0.8', 'User-Agent': 'Mozilla/5.0 (Windows NT 6.1) AppleWebKit/537.1 (KHTML, like Gecko) Chrome/21.0.1180.60 Safari/537.1', 'Accept-Charset': 'UTF-8,*;q=0.5', 'Connection': 'keep-alive', 'Cache-Control': 'max-age=0', 'If-None-Match': '"066fe9dcdcfe491731c759c07fceb62b561bf663"'})
    Traceback (most recent call last):
      File "/usr/lib/python2.6/site-packages/tornado/web.py", line 1000, in _stack_context_handle_exception
        raise_exc_info((type, value, traceback))
      File "/usr/lib/python2.6/site-packages/tornado/web.py", line 1118, in wrapper
        return method(self, *args, **kwargs)
      File "/root/bipapa/app.py", line 165, in get
        self.write(img)
      File "/usr/lib/python2.6/site-packages/tornado/web.py", line 487, in write
        raise RuntimeError("Cannot write() after finish().  May be caused "
    RuntimeError: Cannot write() after finish().  May be caused by using async operations without the @asynchronous decorator.
[E 120806 18:13:09 web:718] Cannot send error response after headers written
[W 120806 18:13:09 web:1447] 404 GET /favicon.ico (192.168.32.17) 0.35ms
[I 120806 18:15:15 autoreload:175] /root/bipapa/app.py modified; restarting server
[I 120806 18:15:16 web:1447] 304 GET / (192.168.32.17) 9.46ms
[W 120806 18:15:17 web:1447] 404 GET /favicon.ico (192.168.32.17) 0.94ms
[I 120806 18:15:17 web:1447] 304 GET / (192.168.32.17) 7.15ms
[W 120806 18:15:18 web:1447] 404 GET /favicon.ico (192.168.32.17) 0.34ms
[I 120806 18:15:35 autoreload:175] /root/bipapa/app.py modified; restarting server
[E 120806 18:15:36 web:1064] Uncaught exception GET / (192.168.32.17)
    HTTPRequest(protocol='http', host='10.24.94.36:8888', method='GET', uri='/', version='HTTP/1.1', remote_ip='192.168.32.17', body='', headers={'Accept-Language': 'ja,en-US;q=0.8,en;q=0.6,zh-CN;q=0.4,zh;q=0.2,zh-TW;q=0.2', 'Accept-Encoding': 'gzip,deflate,sdch', 'Host': '10.24.94.36:8888', 'Accept': 'text/html,application/xhtml+xml,application/xml;q=0.9,*/*;q=0.8', 'User-Agent': 'Mozilla/5.0 (Windows NT 6.1) AppleWebKit/537.1 (KHTML, like Gecko) Chrome/21.0.1180.60 Safari/537.1', 'Accept-Charset': 'UTF-8,*;q=0.5', 'Connection': 'keep-alive', 'Cache-Control': 'max-age=0', 'If-None-Match': '"066fe9dcdcfe491731c759c07fceb62b561bf663"'})
    Traceback (most recent call last):
      File "/usr/lib/python2.6/site-packages/tornado/web.py", line 1000, in _stack_context_handle_exception
        raise_exc_info((type, value, traceback))
      File "/usr/lib/python2.6/site-packages/tornado/web.py", line 1118, in wrapper
        return method(self, *args, **kwargs)
      File "/root/bipapa/app.py", line 169, in get
        pool.apply_async(getimg4db(id),callback=self.on_read)
      File "/root/bipapa/app.py", line 141, in getimg4db
        f = fs.get_version(filename="%s" %filename)
      File "/usr/lib64/python2.6/site-packages/gridfs/__init__.py", line 190, in get_version
        raise NoFile("no version %d for filename %r" % (version, filename))
    NoFile: no version -1 for filename '<built-in function id>'
[E 120806 18:15:36 web:1447] 500 GET / (192.168.32.17) 15.74ms
[W 120806 18:15:37 web:1447] 404 GET /favicon.ico (192.168.32.17) 0.41ms
[I 120806 18:16:12 autoreload:175] /root/bipapa/app.py modified; restarting server
[I 120806 18:16:45 web:1447] 200 GET / (192.168.32.17) 9.34ms
[E 120806 18:16:45 web:1064] Uncaught exception GET / (192.168.32.17)
    HTTPRequest(protocol='http', host='10.24.94.36:8888', method='GET', uri='/', version='HTTP/1.1', remote_ip='192.168.32.17', body='', headers={'Accept-Language': 'ja,en-US;q=0.8,en;q=0.6,zh-CN;q=0.4,zh;q=0.2,zh-TW;q=0.2', 'Accept-Encoding': 'gzip,deflate,sdch', 'Host': '10.24.94.36:8888', 'Accept': 'text/html,application/xhtml+xml,application/xml;q=0.9,*/*;q=0.8', 'User-Agent': 'Mozilla/5.0 (Windows NT 6.1) AppleWebKit/537.1 (KHTML, like Gecko) Chrome/21.0.1180.60 Safari/537.1', 'Accept-Charset': 'UTF-8,*;q=0.5', 'Connection': 'keep-alive', 'Cache-Control': 'max-age=0'})
    Traceback (most recent call last):
      File "/usr/lib/python2.6/site-packages/tornado/web.py", line 1000, in _stack_context_handle_exception
        raise_exc_info((type, value, traceback))
      File "/usr/lib/python2.6/site-packages/tornado/web.py", line 1118, in wrapper
        return method(self, *args, **kwargs)
      File "/root/bipapa/app.py", line 165, in get
        self.write(img)
      File "/usr/lib/python2.6/site-packages/tornado/web.py", line 487, in write
        raise RuntimeError("Cannot write() after finish().  May be caused "
    RuntimeError: Cannot write() after finish().  May be caused by using async operations without the @asynchronous decorator.
[E 120806 18:16:45 web:718] Cannot send error response after headers written
[W 120806 18:16:45 web:1447] 404 GET /favicon.ico (192.168.32.17) 0.43ms
[I 120806 18:16:46 web:1447] 304 GET / (192.168.32.17) 7.05ms
[E 120806 18:16:46 web:1064] Uncaught exception GET / (192.168.32.17)
    HTTPRequest(protocol='http', host='10.24.94.36:8888', method='GET', uri='/', version='HTTP/1.1', remote_ip='192.168.32.17', body='', headers={'Accept-Language': 'ja,en-US;q=0.8,en;q=0.6,zh-CN;q=0.4,zh;q=0.2,zh-TW;q=0.2', 'Accept-Encoding': 'gzip,deflate,sdch', 'Host': '10.24.94.36:8888', 'Accept': 'text/html,application/xhtml+xml,application/xml;q=0.9,*/*;q=0.8', 'User-Agent': 'Mozilla/5.0 (Windows NT 6.1) AppleWebKit/537.1 (KHTML, like Gecko) Chrome/21.0.1180.60 Safari/537.1', 'Accept-Charset': 'UTF-8,*;q=0.5', 'Connection': 'keep-alive', 'Cache-Control': 'max-age=0', 'If-None-Match': '"857198b8da3e515e9a3b16a0981530ca83323c8e"'})
    Traceback (most recent call last):
      File "/usr/lib/python2.6/site-packages/tornado/web.py", line 1000, in _stack_context_handle_exception
        raise_exc_info((type, value, traceback))
      File "/usr/lib/python2.6/site-packages/tornado/web.py", line 1118, in wrapper
        return method(self, *args, **kwargs)
      File "/root/bipapa/app.py", line 165, in get
        self.write(img)
      File "/usr/lib/python2.6/site-packages/tornado/web.py", line 487, in write
        raise RuntimeError("Cannot write() after finish().  May be caused "
    RuntimeError: Cannot write() after finish().  May be caused by using async operations without the @asynchronous decorator.
[E 120806 18:16:46 web:718] Cannot send error response after headers written
[W 120806 18:16:46 web:1447] 404 GET /favicon.ico (192.168.32.17) 0.36ms
[I 120806 18:16:46 web:1447] 304 GET / (192.168.32.17) 7.07ms
[E 120806 18:16:46 web:1064] Uncaught exception GET / (192.168.32.17)
    HTTPRequest(protocol='http', host='10.24.94.36:8888', method='GET', uri='/', version='HTTP/1.1', remote_ip='192.168.32.17', body='', headers={'Accept-Language': 'ja,en-US;q=0.8,en;q=0.6,zh-CN;q=0.4,zh;q=0.2,zh-TW;q=0.2', 'Accept-Encoding': 'gzip,deflate,sdch', 'Host': '10.24.94.36:8888', 'Accept': 'text/html,application/xhtml+xml,application/xml;q=0.9,*/*;q=0.8', 'User-Agent': 'Mozilla/5.0 (Windows NT 6.1) AppleWebKit/537.1 (KHTML, like Gecko) Chrome/21.0.1180.60 Safari/537.1', 'Accept-Charset': 'UTF-8,*;q=0.5', 'Connection': 'keep-alive', 'Cache-Control': 'max-age=0', 'If-None-Match': '"857198b8da3e515e9a3b16a0981530ca83323c8e"'})
    Traceback (most recent call last):
      File "/usr/lib/python2.6/site-packages/tornado/web.py", line 1000, in _stack_context_handle_exception
        raise_exc_info((type, value, traceback))
      File "/usr/lib/python2.6/site-packages/tornado/web.py", line 1118, in wrapper
        return method(self, *args, **kwargs)
      File "/root/bipapa/app.py", line 165, in get
        self.write(img)
      File "/usr/lib/python2.6/site-packages/tornado/web.py", line 487, in write
        raise RuntimeError("Cannot write() after finish().  May be caused "
    RuntimeError: Cannot write() after finish().  May be caused by using async operations without the @asynchronous decorator.
[E 120806 18:16:46 web:718] Cannot send error response after headers written
[W 120806 18:16:47 web:1447] 404 GET /favicon.ico (192.168.32.17) 0.35ms
[I 120806 18:16:54 web:1447] 200 GET / (192.168.32.17) 6.93ms
[E 120806 18:16:54 web:1064] Uncaught exception GET / (192.168.32.17)
    HTTPRequest(protocol='http', host='10.24.94.36:8888', method='GET', uri='/', version='HTTP/1.1', remote_ip='192.168.32.17', body='', headers={'Accept-Language': 'ja,en-US;q=0.8,en;q=0.6,zh-CN;q=0.4,zh;q=0.2,zh-TW;q=0.2', 'Accept-Encoding': 'gzip,deflate,sdch', 'Host': '10.24.94.36:8888', 'Accept': '*/*', 'User-Agent': 'Mozilla/5.0 (Windows NT 6.1) AppleWebKit/537.1 (KHTML, like Gecko) Chrome/21.0.1180.60 Safari/537.1', 'Accept-Charset': 'UTF-8,*;q=0.5', 'Connection': 'keep-alive', 'Referer': 'http://10.24.94.36:8888/', 'Cache-Control': 'max-age=0', 'If-None-Match': '"066fe9dcdcfe491731c759c07fceb62b561bf663"'})
    Traceback (most recent call last):
      File "/usr/lib/python2.6/site-packages/tornado/web.py", line 1000, in _stack_context_handle_exception
        raise_exc_info((type, value, traceback))
      File "/usr/lib/python2.6/site-packages/tornado/web.py", line 1118, in wrapper
        return method(self, *args, **kwargs)
      File "/root/bipapa/app.py", line 165, in get
        self.write(img)
      File "/usr/lib/python2.6/site-packages/tornado/web.py", line 487, in write
        raise RuntimeError("Cannot write() after finish().  May be caused "
    RuntimeError: Cannot write() after finish().  May be caused by using async operations without the @asynchronous decorator.
[E 120806 18:16:54 web:718] Cannot send error response after headers written
[I 120806 18:24:36 web:1447] 304 GET / (192.168.32.17) 7.75ms
[E 120806 18:24:36 web:1064] Uncaught exception GET / (192.168.32.17)
    HTTPRequest(protocol='http', host='10.24.94.36:8888', method='GET', uri='/', version='HTTP/1.1', remote_ip='192.168.32.17', body='', headers={'Accept-Language': 'ja,en-US;q=0.8,en;q=0.6,zh-CN;q=0.4,zh;q=0.2,zh-TW;q=0.2', 'Accept-Encoding': 'gzip,deflate,sdch', 'Host': '10.24.94.36:8888', 'Accept': 'text/html,application/xhtml+xml,application/xml;q=0.9,*/*;q=0.8', 'User-Agent': 'Mozilla/5.0 (Windows NT 6.1) AppleWebKit/537.1 (KHTML, like Gecko) Chrome/21.0.1180.60 Safari/537.1', 'Accept-Charset': 'UTF-8,*;q=0.5', 'Connection': 'keep-alive', 'Cache-Control': 'max-age=0', 'If-None-Match': '"857198b8da3e515e9a3b16a0981530ca83323c8e"'})
    Traceback (most recent call last):
      File "/usr/lib/python2.6/site-packages/tornado/web.py", line 1000, in _stack_context_handle_exception
        raise_exc_info((type, value, traceback))
      File "/usr/lib/python2.6/site-packages/tornado/web.py", line 1118, in wrapper
        return method(self, *args, **kwargs)
      File "/root/bipapa/app.py", line 165, in get
        self.write(img)
      File "/usr/lib/python2.6/site-packages/tornado/web.py", line 487, in write
        raise RuntimeError("Cannot write() after finish().  May be caused "
    RuntimeError: Cannot write() after finish().  May be caused by using async operations without the @asynchronous decorator.
[E 120806 18:24:36 web:718] Cannot send error response after headers written
[W 120806 18:24:37 web:1447] 404 GET /favicon.ico (192.168.32.17) 0.37ms
[I 120806 18:24:38 web:1447] 304 GET / (192.168.32.17) 6.93ms
[E 120806 18:24:38 web:1064] Uncaught exception GET / (192.168.32.17)
    HTTPRequest(protocol='http', host='10.24.94.36:8888', method='GET', uri='/', version='HTTP/1.1', remote_ip='192.168.32.17', body='', headers={'Accept-Language': 'ja,en-US;q=0.8,en;q=0.6,zh-CN;q=0.4,zh;q=0.2,zh-TW;q=0.2', 'Accept-Encoding': 'gzip,deflate,sdch', 'Host': '10.24.94.36:8888', 'Accept': 'text/html,application/xhtml+xml,application/xml;q=0.9,*/*;q=0.8', 'User-Agent': 'Mozilla/5.0 (Windows NT 6.1) AppleWebKit/537.1 (KHTML, like Gecko) Chrome/21.0.1180.60 Safari/537.1', 'Accept-Charset': 'UTF-8,*;q=0.5', 'Connection': 'keep-alive', 'Cache-Control': 'max-age=0', 'If-None-Match': '"857198b8da3e515e9a3b16a0981530ca83323c8e"'})
    Traceback (most recent call last):
      File "/usr/lib/python2.6/site-packages/tornado/web.py", line 1000, in _stack_context_handle_exception
        raise_exc_info((type, value, traceback))
      File "/usr/lib/python2.6/site-packages/tornado/web.py", line 1118, in wrapper
        return method(self, *args, **kwargs)
      File "/root/bipapa/app.py", line 165, in get
        self.write(img)
      File "/usr/lib/python2.6/site-packages/tornado/web.py", line 487, in write
        raise RuntimeError("Cannot write() after finish().  May be caused "
    RuntimeError: Cannot write() after finish().  May be caused by using async operations without the @asynchronous decorator.
[E 120806 18:24:38 web:718] Cannot send error response after headers written
[W 120806 18:24:38 web:1447] 404 GET /favicon.ico (192.168.32.17) 0.35ms
[I 120806 18:30:47 web:1447] 304 GET / (192.168.32.17) 7.52ms
[E 120806 18:30:47 web:1064] Uncaught exception GET / (192.168.32.17)
    HTTPRequest(protocol='http', host='10.24.94.36:8888', method='GET', uri='/', version='HTTP/1.1', remote_ip='192.168.32.17', body='', headers={'Accept-Language': 'ja,en-US;q=0.8,en;q=0.6,zh-CN;q=0.4,zh;q=0.2,zh-TW;q=0.2', 'Accept-Encoding': 'gzip,deflate,sdch', 'Host': '10.24.94.36:8888', 'Accept': '*/*', 'User-Agent': 'Mozilla/5.0 (Windows NT 6.1) AppleWebKit/537.1 (KHTML, like Gecko) Chrome/21.0.1180.60 Safari/537.1', 'Accept-Charset': 'UTF-8,*;q=0.5', 'Connection': 'keep-alive', 'Referer': 'http://10.24.94.36:8888/', 'If-None-Match': '"857198b8da3e515e9a3b16a0981530ca83323c8e"'})
    Traceback (most recent call last):
      File "/usr/lib/python2.6/site-packages/tornado/web.py", line 1000, in _stack_context_handle_exception
        raise_exc_info((type, value, traceback))
      File "/usr/lib/python2.6/site-packages/tornado/web.py", line 1118, in wrapper
        return method(self, *args, **kwargs)
      File "/root/bipapa/app.py", line 165, in get
        self.write(img)
      File "/usr/lib/python2.6/site-packages/tornado/web.py", line 487, in write
        raise RuntimeError("Cannot write() after finish().  May be caused "
    RuntimeError: Cannot write() after finish().  May be caused by using async operations without the @asynchronous decorator.
[E 120806 18:30:47 web:718] Cannot send error response after headers written
[I 120806 18:44:34 autoreload:175] /root/bipapa/app.py modified; restarting server
[I 120806 18:44:34 web:1447] 200 GET / (192.168.32.17) 9.38ms
[E 120806 18:44:34 web:1064] Uncaught exception GET / (192.168.32.17)
    HTTPRequest(protocol='http', host='10.24.94.36:8888', method='GET', uri='/', version='HTTP/1.1', remote_ip='192.168.32.17', body='', headers={'Accept-Language': 'ja,en-US;q=0.8,en;q=0.6,zh-CN;q=0.4,zh;q=0.2,zh-TW;q=0.2', 'Accept-Encoding': 'gzip,deflate,sdch', 'Host': '10.24.94.36:8888', 'Accept': 'text/html,application/xhtml+xml,application/xml;q=0.9,*/*;q=0.8', 'User-Agent': 'Mozilla/5.0 (Windows NT 6.1) AppleWebKit/537.1 (KHTML, like Gecko) Chrome/21.0.1180.60 Safari/537.1', 'Accept-Charset': 'UTF-8,*;q=0.5', 'Connection': 'keep-alive', 'Cache-Control': 'max-age=0', 'If-None-Match': '"857198b8da3e515e9a3b16a0981530ca83323c8e"'})
    Traceback (most recent call last):
      File "/usr/lib/python2.6/site-packages/tornado/web.py", line 1000, in _stack_context_handle_exception
        raise_exc_info((type, value, traceback))
      File "/usr/lib/python2.6/site-packages/tornado/web.py", line 1118, in wrapper
        return method(self, *args, **kwargs)
      File "/root/bipapa/app.py", line 165, in get
        self.write(img)
      File "/usr/lib/python2.6/site-packages/tornado/web.py", line 487, in write
        raise RuntimeError("Cannot write() after finish().  May be caused "
    RuntimeError: Cannot write() after finish().  May be caused by using async operations without the @asynchronous decorator.
[E 120806 18:44:34 web:718] Cannot send error response after headers written
[W 120806 18:44:35 web:1447] 404 GET /favicon.ico (192.168.32.17) 0.41ms
[I 120806 18:51:31 autoreload:175] /root/bipapa/app.py modified; restarting server
[E 120806 18:51:33 web:1064] Uncaught exception GET / (192.168.32.17)
    HTTPRequest(protocol='http', host='10.24.94.36:8888', method='GET', uri='/', version='HTTP/1.1', remote_ip='192.168.32.17', body='', headers={'Accept-Language': 'ja,en-US;q=0.8,en;q=0.6,zh-CN;q=0.4,zh;q=0.2,zh-TW;q=0.2', 'Accept-Encoding': 'gzip,deflate,sdch', 'Host': '10.24.94.36:8888', 'Accept': '*/*', 'User-Agent': 'Mozilla/5.0 (Windows NT 6.1) AppleWebKit/537.1 (KHTML, like Gecko) Chrome/21.0.1180.60 Safari/537.1', 'Accept-Charset': 'UTF-8,*;q=0.5', 'Connection': 'keep-alive', 'Referer': 'http://10.24.94.36:8888/', 'Cache-Control': 'max-age=0', 'If-None-Match': '"857198b8da3e515e9a3b16a0981530ca83323c8e"'})
    Traceback (most recent call last):
      File "/usr/lib/python2.6/site-packages/tornado/web.py", line 1000, in _stack_context_handle_exception
        raise_exc_info((type, value, traceback))
      File "/usr/lib/python2.6/site-packages/tornado/web.py", line 1118, in wrapper
        return method(self, *args, **kwargs)
      File "/root/bipapa/app.py", line 161, in get
        id_list = fs.list()
    NameError: global name 'fs' is not defined
[E 120806 18:51:33 web:1447] 500 GET / (192.168.32.17) 14.74ms
[E 120806 18:51:33 web:1064] Uncaught exception GET / (192.168.32.17)
    HTTPRequest(protocol='http', host='10.24.94.36:8888', method='GET', uri='/', version='HTTP/1.1', remote_ip='192.168.32.17', body='', headers={'Accept-Language': 'ja,en-US;q=0.8,en;q=0.6,zh-CN;q=0.4,zh;q=0.2,zh-TW;q=0.2', 'Accept-Encoding': 'gzip,deflate,sdch', 'Host': '10.24.94.36:8888', 'Accept': 'text/html,application/xhtml+xml,application/xml;q=0.9,*/*;q=0.8', 'User-Agent': 'Mozilla/5.0 (Windows NT 6.1) AppleWebKit/537.1 (KHTML, like Gecko) Chrome/21.0.1180.60 Safari/537.1', 'Accept-Charset': 'UTF-8,*;q=0.5', 'Connection': 'keep-alive', 'Cache-Control': 'max-age=0', 'If-None-Match': '"066fe9dcdcfe491731c759c07fceb62b561bf663"'})
    Traceback (most recent call last):
      File "/usr/lib/python2.6/site-packages/tornado/web.py", line 1000, in _stack_context_handle_exception
        raise_exc_info((type, value, traceback))
      File "/usr/lib/python2.6/site-packages/tornado/web.py", line 1118, in wrapper
        return method(self, *args, **kwargs)
      File "/root/bipapa/app.py", line 161, in get
        id_list = fs.list()
    NameError: global name 'fs' is not defined
[E 120806 18:51:33 web:1447] 500 GET / (192.168.32.17) 8.21ms
[W 120806 18:51:33 web:1447] 404 GET /favicon.ico (192.168.32.17) 0.46ms
[I 120806 18:51:59 autoreload:175] /root/bipapa/app.py modified; restarting server
[E 120806 18:51:59 web:1064] Uncaught exception GET / (192.168.32.17)
    HTTPRequest(protocol='http', host='10.24.94.36:8888', method='GET', uri='/', version='HTTP/1.1', remote_ip='192.168.32.17', body='', headers={'Accept-Language': 'ja,en-US;q=0.8,en;q=0.6,zh-CN;q=0.4,zh;q=0.2,zh-TW;q=0.2', 'Accept-Encoding': 'gzip,deflate,sdch', 'Host': '10.24.94.36:8888', 'Accept': 'text/html,application/xhtml+xml,application/xml;q=0.9,*/*;q=0.8', 'User-Agent': 'Mozilla/5.0 (Windows NT 6.1) AppleWebKit/537.1 (KHTML, like Gecko) Chrome/21.0.1180.60 Safari/537.1', 'Accept-Charset': 'UTF-8,*;q=0.5', 'Connection': 'keep-alive', 'Cache-Control': 'max-age=0'})
    Traceback (most recent call last):
      File "/usr/lib/python2.6/site-packages/tornado/web.py", line 1000, in _stack_context_handle_exception
        raise_exc_info((type, value, traceback))
      File "/usr/lib/python2.6/site-packages/tornado/web.py", line 1118, in wrapper
        return method(self, *args, **kwargs)
      File "/root/bipapa/app.py", line 163, in get
        self.one_read(id)
    AttributeError: 'MainHandler' object has no attribute 'one_read'
[E 120806 18:51:59 web:1447] 500 GET / (192.168.32.17) 6.45ms
[W 120806 18:52:00 web:1447] 404 GET /favicon.ico (192.168.32.17) 0.43ms
[E 120806 18:52:00 web:1064] Uncaught exception GET / (192.168.32.17)
    HTTPRequest(protocol='http', host='10.24.94.36:8888', method='GET', uri='/', version='HTTP/1.1', remote_ip='192.168.32.17', body='', headers={'Accept-Language': 'ja,en-US;q=0.8,en;q=0.6,zh-CN;q=0.4,zh;q=0.2,zh-TW;q=0.2', 'Accept-Encoding': 'gzip,deflate,sdch', 'Host': '10.24.94.36:8888', 'Accept': 'text/html,application/xhtml+xml,application/xml;q=0.9,*/*;q=0.8', 'User-Agent': 'Mozilla/5.0 (Windows NT 6.1) AppleWebKit/537.1 (KHTML, like Gecko) Chrome/21.0.1180.60 Safari/537.1', 'Accept-Charset': 'UTF-8,*;q=0.5', 'Connection': 'keep-alive', 'Cache-Control': 'max-age=0'})
    Traceback (most recent call last):
      File "/usr/lib/python2.6/site-packages/tornado/web.py", line 1000, in _stack_context_handle_exception
        raise_exc_info((type, value, traceback))
      File "/usr/lib/python2.6/site-packages/tornado/web.py", line 1118, in wrapper
        return method(self, *args, **kwargs)
      File "/root/bipapa/app.py", line 163, in get
        self.one_read(id)
    AttributeError: 'MainHandler' object has no attribute 'one_read'
[E 120806 18:52:00 web:1447] 500 GET / (192.168.32.17) 3.09ms
[W 120806 18:52:00 web:1447] 404 GET /favicon.ico (192.168.32.17) 0.35ms
[E 120806 18:52:01 web:1064] Uncaught exception GET / (192.168.32.17)
    HTTPRequest(protocol='http', host='10.24.94.36:8888', method='GET', uri='/', version='HTTP/1.1', remote_ip='192.168.32.17', body='', headers={'Accept-Language': 'ja,en-US;q=0.8,en;q=0.6,zh-CN;q=0.4,zh;q=0.2,zh-TW;q=0.2', 'Accept-Encoding': 'gzip,deflate,sdch', 'Host': '10.24.94.36:8888', 'Accept': 'text/html,application/xhtml+xml,application/xml;q=0.9,*/*;q=0.8', 'User-Agent': 'Mozilla/5.0 (Windows NT 6.1) AppleWebKit/537.1 (KHTML, like Gecko) Chrome/21.0.1180.60 Safari/537.1', 'Accept-Charset': 'UTF-8,*;q=0.5', 'Connection': 'keep-alive', 'Cache-Control': 'max-age=0'})
    Traceback (most recent call last):
      File "/usr/lib/python2.6/site-packages/tornado/web.py", line 1000, in _stack_context_handle_exception
        raise_exc_info((type, value, traceback))
      File "/usr/lib/python2.6/site-packages/tornado/web.py", line 1118, in wrapper
        return method(self, *args, **kwargs)
      File "/root/bipapa/app.py", line 163, in get
        self.one_read(id)
    AttributeError: 'MainHandler' object has no attribute 'one_read'
[E 120806 18:52:01 web:1447] 500 GET / (192.168.32.17) 3.19ms
[W 120806 18:52:01 web:1447] 404 GET /favicon.ico (192.168.32.17) 0.34ms
[I 120806 18:52:16 autoreload:175] /root/bipapa/app.py modified; restarting server
[E 120806 18:52:16 web:1064] Uncaught exception GET / (192.168.32.17)
    HTTPRequest(protocol='http', host='10.24.94.36:8888', method='GET', uri='/', version='HTTP/1.1', remote_ip='192.168.32.17', body='', headers={'Accept-Language': 'ja,en-US;q=0.8,en;q=0.6,zh-CN;q=0.4,zh;q=0.2,zh-TW;q=0.2', 'Accept-Encoding': 'gzip,deflate,sdch', 'Host': '10.24.94.36:8888', 'Accept': 'text/html,application/xhtml+xml,application/xml;q=0.9,*/*;q=0.8', 'User-Agent': 'Mozilla/5.0 (Windows NT 6.1) AppleWebKit/537.1 (KHTML, like Gecko) Chrome/21.0.1180.60 Safari/537.1', 'Accept-Charset': 'UTF-8,*;q=0.5', 'Connection': 'keep-alive', 'Cache-Control': 'max-age=0'})
    Traceback (most recent call last):
      File "/usr/lib/python2.6/site-packages/tornado/web.py", line 1000, in _stack_context_handle_exception
        raise_exc_info((type, value, traceback))
      File "/usr/lib/python2.6/site-packages/tornado/web.py", line 1118, in wrapper
        return method(self, *args, **kwargs)
      File "/root/bipapa/app.py", line 163, in get
        self.one_read(id)
    AttributeError: 'MainHandler' object has no attribute 'one_read'
[E 120806 18:52:16 web:1447] 500 GET / (192.168.32.17) 6.20ms
[W 120806 18:52:17 web:1447] 404 GET /favicon.ico (192.168.32.17) 0.43ms
[I 120807 08:57:08 autoreload:175] /root/bipapa/app.py modified; restarting server
